Workbook
Name A_Att: Attendance_Leave!$K$2:$K$501
Name A_Dept: Attendance_Leave!$C$2:$C$501
Name A_Flag: Attendance_Leave!$O$2:$O$501
Name A_OT: Attendance_Leave!$N$2:$N$501
Name A_Planned: Attendance_Leave!$F$2:$F$501
Name A_Sick: Attendance_Leave!$G$2:$G$501
Name A_Status: Attendance_Leave!$D$2:$D$501
Name A_Unpl: Attendance_Leave!$H$2:$H$501
Name A_WFH: Attendance_Leave!$L$2:$L$501
Name AsOf: Settings!$B$4
Name BandLevels: Settings!$A$14:$A$20
Name BandMax: Settings!$E$14:$E$20
Name BandMid: Settings!$D$14:$D$20
Name BandMin: Settings!$C$14:$C$20
Name C_Bonus: Compensation!$P$2:$P$501
Name C_Compa: Compensation!$J$2:$J$501
Name C_CTC: Compensation!$F$2:$F$501
Name C_Dept: Compensation!$C$2:$C$501
Name C_Hike: Compensation!$M$2:$M$501
Name C_Level: Compensation!$D$2:$D$501
Name C_Pos: Compensation!$K$2:$K$501
Name C_Rev: Compensation!$N$2:$N$501
Name C_Status: Compensation!$E$2:$E$501
Name CompaThreshold: Settings!$B$9
Name DeptList: Settings!$A$23:$A$33
Name E_Cat: Engagement!$O$2:$O$501
Name E_Dept: Engagement!$C$2:$C$501
Name E_Dim1: Engagement!$G$2:$G$501
Name E_Dim2: Engagement!$H$2:$H$501
Name E_Dim3: Engagement!$I$2:$I$501
Name E_Dim4: Engagement!$J$2:$J$501
Name E_Dim5: Engagement!$K$2:$K$501
Name E_Dim6: Engagement!$L$2:$L$501
Name E_eNPS: Engagement!$N$2:$N$501
Name E_Overall: Engagement!$M$2:$M$501
Name E_Rating: Engagement!$P$2:$P$501
Name E_Risk: Engagement!$S$2:$S$501
Name E_Status: Engagement!$E$2:$E$501
Name E_Survey: Engagement!$F$2:$F$501
Name EmpList: OFFSET(Calc_Engine!$J$2,0,0,MAX(1,COUNT(Calc_Engine!$H$2:$H$501)),1)
Name EngThreshold: Settings!$B$8
Name M_Dept: Employee_Master!$I$2:$I$501
Name M_DOJ: Employee_Master!$M$2:$M$501
Name M_Email: Employee_Master!$C$2:$C$501
Name M_Exit: Employee_Master!$P$2:$P$501
Name M_Gender: Employee_Master!$J$2:$J$501
Name M_ID: Employee_Master!$A$2:$A$501
Name M_Level: Employee_Master!$G$2:$G$501
Name M_LevelNo: Employee_Master!$H$2:$H$501
Name M_Loc: Employee_Master!$K$2:$K$501
Name M_Mgr: Employee_Master!$D$2:$D$501
Name M_Name: Employee_Master!$B$2:$B$501
Name M_Reports: Employee_Master!$S$2:$S$501
Name M_Status: Employee_Master!$O$2:$O$501
Name M_TBand: Employee_Master!$R$2:$R$501
Name M_Tenure: Employee_Master!$Q$2:$Q$501
Name M_Title: Employee_Master!$F$2:$F$501
Name M_Type: Employee_Master!$L$2:$L$501
Name MaxLvl: Settings!$B$7
Name MinRating: Settings!$B$5

Sheet Read_Me
B1: HR Analytics Showcase Workbook
B2: Built by Sonali K · Excel formulas, named ranges, dynamic dropdowns, conditional formatting, charts and VBA macros · all data is fictional
B5: HOW TO USE
B6: 1. Dashboard | C6: Pick a Department in the yellow box (or All Departments for the whole organisation). All 21 KPI tiles, 12 charts, the 9-box grid and the scorecard recalculate instantly.
B7: 2. Employee profile | C7: Pick an Employee in the second yellow box. The list only shows people in the selected department. The profile card pulls data from all eight data sheets.
B8: 3. Employee_Explorer | C8: Lists every employee in the selected department with key metrics. Filter or sort with the header arrows.
B9: 4. Settings | C9: Change the promotion rules, pay bands, flight-risk thresholds or the as-of date. Every formula uses these values.
B10: 5. Macros (optional) | C10: Import HR_Dashboard_Macros.bas (Alt+F11 > File > Import File), save as .xlsm, then run BuildDashboardButtons once to add buttons. Macros add: next/previous employee, search by name, promotion list, department report export, flight-risk list, PDF export and reset.
B12: SHEETS
B13: Employee_Master | C13: 500 employees: ID, name, email, manager, manager ID, designation, level, department, gender, location, type, joining date, age. Status, exit date, tenure and direct reports are formulas.
B14: Performance | C14: Rating (1-5), label, previous rating and trend, goals achieved, competency, potential, 9-box category, time in level and a rules-based Promotion Eligibility with the reason.
B15: Compensation | C15: Annual CTC against level pay bands, compa-ratio, band position, increment %, revised CTC, bonus and ESOP eligibility.
B16: Attendance_Leave | C16: Working days, planned/sick/unplanned leave, attendance %, WFH, late marks, overtime and an absence flag.
B17: Training | C17: Programs, courses, hours, cost, assessment score, POSH and InfoSec completion, compliance status, certifications.
B18: Engagement | C18: Six survey dimensions, overall engagement, eNPS and category, plus a formula-based flight-risk score.
B19: Exits_Attrition | C19: 64 exits in the last 12 months: type, reason, regrettable loss, notice, rehire eligibility, exit interview.
B20: Recruitment | C20: 140 requisitions: funnel (applicants to offers), status, source, time to fill, offer acceptance and cost per hire.
B21: Calc_Engine | C21: Behind-the-scenes helper: selection criteria, the filtered employee list for the dropdown, and the data behind every chart.
B23: SKILLS SHOWN
B24: Excel techniques | C24: INDEX/MATCH lookups across sheets, COUNTIFS/AVERAGEIFS/SUMIFS with a wildcard 'All' filter, 60+ named ranges, dependent dropdown via OFFSET, 9-box matrix lookup, dynamic chart titles, conditional formatting (colour scales, data bars, formula rules), single-parameter model in Settings.
B25: HR analytics | C25: Headcount, attrition (average-headcount basis), regrettable loss, hiring funnel and source effectiveness, time to fill, pay equity (compa-ratio), promotion readiness, talent 9-box, engagement and eNPS, flight-risk scoring, compliance training coverage.
B27: COLOUR KEY
B28: Blue text / yellow fill | C28: Inputs you can change.
B29: Teal column headers | C29: Columns calculated by formulas (do not type over them).
B30: Green text | C30: Values pulled from another sheet.

Sheet Dashboard
B1: HR ANALYTICS DASHBOARD
B2: =" SampleCorp (fictional sample data) · 500 employees · As of "&TEXT(AsOf,"dd-mmm-yyyy")&" · Viewing: "&SelLabel -> SampleCorp (fictional sample data) · 500 employees · As of 30-Sep-2026 · Viewing: All Departments
B4: Department ▸ | D4: All Departments | H4: Employee ▸ | J4: EMP1001 | Vidya Kulkarni | O4: Pick a department, then an employee. Every tile, chart and the profile card update instantly (no macro needed).
B5: Macro buttons appear on this strip after you import HR_Dashboard_Macros.bas and run BuildDashboardButtons once (see Read_Me).
B6: Total Employees (12M) | E6: Active Headcount | H6: Exits (Last 12M) | K6: Attrition Rate (12M) | N6: New Hires (12M) | Q6: Avg Tenure (Yrs) | T6: Female Representation
B7: =COUNTIFS(M_Dept,SelCrit) -> 500 | E7: =COUNTIFS(M_Dept,SelCrit,M_Status,"Active") -> 436 | H7: =COUNTIFS(X_Dept,SelCrit) -> 64 | K7: =IFERROR(COUNTIFS(X_Dept,SelCrit)/((COUNTIFS(M_Dept,SelCrit,M_DOJ,"<"&PeriodStart)+COUNTIFS(M_Dept,SelCrit,M_Status,"Active"))/2),0) -> 0.15705521 | N7: =COUNTIFS(M_Dept,SelCrit,M_DOJ,">="&PeriodStart) -> 121 | Q7: =IFERROR(AVERAGEIFS(M_Tenure,M_Dept,SelCrit,M_Status,"Active"),0) -> 2.6311927 | T7: =IFERROR(COUNTIFS(M_Dept,SelCrit,M_Gender,"Female",M_Status,"Active")/COUNTIFS(M_Dept,SelCrit,M_Status,"Active"),0) -> 0.46559633
B8: ="Includes "&COUNTIFS(X_Dept,SelCrit)&" who exited" -> Includes 64 who exited | E8: ="Contract staff: "&COUNTIFS(M_Dept,SelCrit,M_Status,"Active",M_Type,"Contract") -> Contract staff: 28 | H8: ="Voluntary "&COUNTIFS(X_Dept,SelCrit,X_Type,"Voluntary")&" · Regrettable "&COUNTIFS(X_Dept,SelCrit,X_Regret,"Yes") -> Voluntary 52 · Regrettable 28 | K8: ="Exits ÷ average headcount" -> Exits ÷ average headcount | N8: ="Joined since "&TEXT(PeriodStart,"dd-mmm-yy") -> Joined since 30-Sep-25 | Q8: ="Under 1 year: "&COUNTIFS(M_Dept,SelCrit,M_TBand,"Under 1 Yr",M_Status,"Active")&" people" -> Under 1 year: 101 people | T8: ="Women "&COUNTIFS(M_Dept,SelCrit,M_Gender,"Female",M_Status,"Active")&" · Men "&COUNTIFS(M_Dept,SelCrit,M_Gender,"Male",M_Status,"Active") -> Women 203 · Men 233
B10: Avg Performance Rating | E10: Promotion Eligible | H10: High Performers (4-5) | K10: Avg Annual CTC (₹ L) | N10: Avg Compa-Ratio | Q10: Attendance Rate | T10: Employee NPS (eNPS)
B11: =IFERROR(AVERAGEIFS(P_Rating,P_Dept,SelCrit),0) -> 3.234 | E11: =COUNTIFS(P_Dept,SelCrit,P_Elig,"Eligible") -> 82 | H11: =IFERROR(COUNTIFS(P_Dept,SelCrit,P_Rating,">=4",P_Status,"Active")/COUNTIFS(M_Dept,SelCrit,M_Status,"Active"),0) -> 0.39220183 | K11: =IFERROR(AVERAGEIFS(C_CTC,C_Dept,SelCrit,C_Status,"Active")/100000,0) -> 16.457752 | N11: =IFERROR(AVERAGEIFS(C_Compa,C_Dept,SelCrit,C_Status,"Active"),0) -> 0.9687156 | Q11: =IFERROR(AVERAGEIFS(A_Att,A_Dept,SelCrit,A_Status,"Active"),0) -> 0.89245868 | T11: =IFERROR((COUNTIFS(E_Dept,SelCrit,E_Cat,"Promoter",E_Status,"Active",E_Survey,"Yes")-COUNTIFS(E_Dept,SelCrit,E_Cat,"Detractor",E_Status,"Active",E_Survey,"Yes"))/COUNTIFS(E_Dept,SelCrit,E_Status,"Active",E_Survey,"Yes")*100,0) -> 22.727273
B12: ="Low performers (1-2): "&COUNTIFS(P_Dept,SelCrit,P_Rating,"<=2") -> Low performers (1-2): 95 | E12: =TEXT(IFERROR(COUNTIFS(P_Dept,SelCrit,P_Elig,"Eligible")/COUNTIFS(M_Dept,SelCrit,M_Status,"Active"),0),"0.0%")&" of active headcount" -> 18.8% of active headcount | H12: =COUNTIFS(P_Dept,SelCrit,P_Rating,">=4",P_Status,"Active")&" active employees" -> 171 active employees | K12: ="Annual payroll ₹"&TEXT(SUMIFS(C_CTC,C_Dept,SelCrit,C_Status,"Active")/10000000,"0.00")&" Cr" -> Annual payroll ₹71.76 Cr | N12: ="Below band: "&COUNTIFS(C_Dept,SelCrit,C_Pos,"Below Band",C_Status,"Active")&" · Above: "&COUNTIFS(C_Dept,SelCrit,C_Pos,"Above Band",C_Status,"Active") -> Below band: 10 · Above: 6 | Q12: ="Avg unplanned leave "&TEXT(IFERROR(AVERAGEIFS(A_Unpl,A_Dept,SelCrit,A_Status,"Active"),0),"0.0")&" days" -> Avg unplanned leave 3.1 days | T12: ="Promoters "&COUNTIFS(E_Dept,SelCrit,E_Cat,"Promoter",E_Status,"Active",E_Survey,"Yes")&" · Detractors "&COUNTIFS(E_Dept,SelCrit,E_Cat,"Detractor",E_Status,"Active",E_Survey,"Yes") -> Promoters 148 · Detractors 63
B14: Avg Training Hours | E14: Compliance Training | H14: Engagement Score (/5) | K14: High Flight Risk | N14: Open Requisitions | Q14: Avg Time to Fill (Days) | T14: Offer Acceptance
B15: =IFERROR(AVERAGEIFS(T_Hours,T_Dept,SelCrit),0) -> 27.746 | E15: =IFERROR(COUNTIFS(T_Dept,SelCrit,T_Comp,"Compliant",T_Status,"Active")/COUNTIFS(M_Dept,SelCrit,M_Status,"Active"),0) -> 0.86926606 | H15: =IFERROR(AVERAGEIFS(E_Overall,E_Dept,SelCrit,E_Status,"Active"),0) -> 3.2512844 | K15: =COUNTIFS(E_Dept,SelCrit,E_Risk,"High") -> 27 | N15: =COUNTIFS(R_Dept,SelCrit,R_Status,"Open") -> 43 | Q15: =IFERROR(AVERAGEIFS(R_TTF,R_Dept,SelCrit,R_Status,"Filled"),0) -> 41.025974 | T15: =IFERROR(SUMIFS(R_Acc,R_Dept,SelCrit)/SUMIFS(R_Offers,R_Dept,SelCrit),0) -> 0.63114754
B16: ="Spend ₹"&TEXT(SUMIFS(T_Cost,T_Dept,SelCrit)/100000,"0.0")&" L · "&TEXT(SUMIFS(T_Hours,T_Dept,SelCrit),"#,##0")&" hrs" -> Spend ₹98.6 L · 13,873 hrs | E16: ="Pending (POSH / InfoSec): "&COUNTIFS(T_Dept,SelCrit,T_Comp,"Pending",T_Status,"Active") -> Pending (POSH / InfoSec): 57 | H16: ="Survey participation "&TEXT(IFERROR(COUNTIFS(E_Dept,SelCrit,E_Survey,"Yes",E_Status,"Active")/COUNTIFS(M_Dept,SelCrit,M_Status,"Active"),0),"0%") -> Survey participation 86% | K16: ="Of which rated 4-5: "&COUNTIFS(E_Dept,SelCrit,E_Risk,"High",E_Rating,">=4") -> Of which rated 4-5: 13 | N16: ="High priority: "&COUNTIFS(R_Dept,SelCrit,R_Status,"Open",R_Prio,"High")&" · On hold: "&COUNTIFS(R_Dept,SelCrit,R_Status,"On Hold") -> High priority: 10 · On hold: 11 | Q16: ="Filled requisitions: "&COUNTIFS(R_Dept,SelCrit,R_Status,"Filled") -> Filled requisitions: 77 | T16: ="Avg cost per hire ₹"&TEXT(IFERROR(AVERAGEIFS(R_Cost,R_Dept,SelCrit,R_Status,"Filled"),0),"#,##0") -> Avg cost per hire ₹29,143
B19: EMPLOYEE PROFILE | M19: 9-BOX TALENT GRID (active employees in view)
B20: Employee ID | D20: =SelEmp -> EMP1001 | G20: Rating | I20: =INDEX(P_Rating,SelRow)&" - "&INDEX(P_Label,SelRow) -> 5 - Outstanding | N20: Low Potential | Q20: Medium Potential | T20: High Potential
B21: Name | D21: =INDEX(M_Name,SelRow) -> Vidya Kulkarni | G21: Previous · Trend | I21: =INDEX(P_Prev,SelRow)&" · "&INDEX(P_Trend,SelRow) -> 5 · Stable | M21: High Performance | N21: ="Trusted Professional"&CHAR(10)&COUNTIFS(P_Dept,SelCrit,P_9Box,"Trusted Professional",P_Status,"Active")&" people" -> Trusted Professional 12 people | Q21: ="High Performer"&CHAR(10)&COUNTIFS(P_Dept,SelCrit,P_9Box,"High Performer",P_Status,"Active")&" people" -> High Performer 77 people | T21: ="Star"&CHAR(10)&COUNTIFS(P_Dept,SelCrit,P_9Box,"Star",P_Status,"Active")&" people" -> Star 82 people
B22: Email | D22: =INDEX(M_Email,SelRow) -> vidya.kulkarni@samplecorp.in | G22: Goals Achieved | I22: =INDEX(P_Goals,SelRow) -> 1.1
B23: Designation | D23: =INDEX(M_Title,SelRow) -> Head of People | G23: Potential · 9-Box | I23: =INDEX(P_Pot,SelRow)&" · "&INDEX(P_9Box,SelRow) -> High · Star
B24: Level | D24: =INDEX(M_Level,SelRow) -> L7 | G24: Promotion Eligibility | I24: =INDEX(P_Elig,SelRow) -> Not Eligible | M24: Mid Performance | N24: ="Effective Contributor"&CHAR(10)&COUNTIFS(P_Dept,SelCrit,P_9Box,"Effective Contributor",P_Status,"Active")&" people" -> Effective Contributor 35 people | Q24: ="Core Player"&CHAR(10)&COUNTIFS(P_Dept,SelCrit,P_9Box,"Core Player",P_Status,"Active")&" people" -> Core Player 115 people | T24: ="Future Star"&CHAR(10)&COUNTIFS(P_Dept,SelCrit,P_9Box,"Future Star",P_Status,"Active")&" people" -> Future Star 33 people
B25: Department | D25: =INDEX(M_Dept,SelRow) -> Human Resources | G25: Reason | I25: =INDEX(P_Reason,SelRow) -> Already at top level
B26: Manager | D26: =INDEX(M_Mgr,SelRow) -> Arvind Rao (CEO) | G26: Annual CTC | I26: =INDEX(C_CTC,SelRow) -> 7632000
B27: Location | D27: =INDEX(M_Loc,SelRow) -> Bengaluru | G27: Compa-Ratio · Band | I27: =TEXT(INDEX(C_Compa,SelRow),"0.00")&" · "&INDEX(C_Pos,SelRow) -> 0.93 · Within Band | M27: Low Performance | N27: ="Underperformer"&CHAR(10)&COUNTIFS(P_Dept,SelCrit,P_9Box,"Underperformer",P_Status,"Active")&" people" -> Underperformer 41 people | Q27: ="Inconsistent Player"&CHAR(10)&COUNTIFS(P_Dept,SelCrit,P_9Box,"Inconsistent Player",P_Status,"Active")&" people" -> Inconsistent Player 35 people | T27: ="Rough Diamond"&CHAR(10)&COUNTIFS(P_Dept,SelCrit,P_9Box,"Rough Diamond",P_Status,"Active")&" people" -> Rough Diamond 6 people
B28: Date of Joining | D28: =INDEX(M_DOJ,SelRow) -> 42718 | G28: Attendance · Leave | I28: =TEXT(INDEX(A_Att,SelRow),"0.0%")&" · "&INDEX(A_Unpl,SelRow)&" days" -> 92.8% · 3 days
B29: Tenure (Yrs) | D29: =INDEX(M_Tenure,SelRow) -> 9.8 | G29: Training · Compliance | I29: =INDEX(T_Hours,SelRow)&" hrs · "&INDEX(T_Comp,SelRow) -> 7 hrs · Compliant
B30: Status | D30: =INDEX(M_Status,SelRow) -> Active | G30: Engagement · eNPS | I30: =TEXT(INDEX(E_Overall,SelRow),"0.00")&" /5 · eNPS "&INDEX(E_eNPS,SelRow)&" ("&INDEX(E_Cat,SelRow)&")" -> 3.73 /5 · eNPS 10 (Promoter) | M30: Grid counts active employees in the selected department. The selected employee's box turns bold italic with an amber outline. Performance band: High = rating 4-5, Mid = 3, Low = 1-2; potential comes from the Performance sheet.
B31: Direct Reports | D31: =INDEX(M_Reports,SelRow) -> 1 | G31: Flight Risk | I31: =INDEX(E_Risk,SelRow) -> Low
B32: =Calc_Engine!$B$7
B34: WORKFORCE ANALYTICS (charts follow the department selection)
B104: DEPARTMENT SCORECARD (all departments; selected department highlighted)
B105: Department | D105: Active HC | E105: Exits 12M | F105: Attrition % | G105: Avg Rating | H105: Promo Eligible | I105: Avg CTC (₹ L) | J105: Avg Compa | K105: Attendance % | L105: Engagement | M105: eNPS | N105: High Flight Risk | O105: Open Reqs | P105: Avg Time to Fill | Q105: Female % | R105: Avg Training Hrs | S105: High Perf % | T105: Compliance % | U105: Avg Tenure
B106: Engineering | D106: =COUNTIFS(M_Dept,$B$106,M_Status,"Active") -> 97 | E106: =COUNTIFS(X_Dept,$B$106) -> 13 | F106: =IFERROR(COUNTIFS(X_Dept,$B$106)/((COUNTIFS(M_Dept,$B$106,M_DOJ,"<"&PeriodStart)+COUNTIFS(M_Dept,$B$106,M_Status,"Active"))/2),0) -> 0.14285714 | G106: =IFERROR(AVERAGEIFS(P_Rating,P_Dept,$B$106),0) -> 3.2818182 | H106: =COUNTIFS(P_Dept,$B$106,P_Elig,"Eligible") -> 14 | I106: =IFERROR(AVERAGEIFS(C_CTC,C_Dept,$B$106,C_Status,"Active")/100000,0) -> 18.470619 | J106: =IFERROR(AVERAGEIFS(C_Compa,C_Dept,$B$106,C_Status,"Active"),0) -> 1.1612371 | K106: =IFERROR(AVERAGEIFS(A_Att,A_Dept,$B$106,A_Status,"Active"),0) -> 0.89673349 | L106: =IFERROR(AVERAGEIFS(E_Overall,E_Dept,$B$106,E_Status,"Active"),0) -> 3.235567 | M106: =IFERROR((COUNTIFS(E_Dept,$B$106,E_Cat,"Promoter",E_Status,"Active",E_Survey,"Yes")-COUNTIFS(E_Dept,$B$106,E_Cat,"Detractor",E_Status,"Active",E_Survey,"Yes"))/COUNTIFS(E_Dept,$B$106,E_Status,"Active",E_Survey,"Yes")*100,0) -> 16.470588 | N106: =COUNTIFS(E_Dept,$B$106,E_Risk,"High") -> 3 | O106: =COUNTIFS(R_Dept,$B$106,R_Status,"Open") -> 8 | P106: =IFERROR(AVERAGEIFS(R_TTF,R_Dept,$B$106,R_Status,"Filled"),0) -> 37.941176 | Q106: =IFERROR(COUNTIFS(M_Dept,$B$106,M_Gender,"Female",M_Status,"Active")/COUNTIFS(M_Dept,$B$106,M_Status,"Active"),0) -> 0.44329897 | R106: =IFERROR(AVERAGEIFS(T_Hours,T_Dept,$B$106),0) -> 27.681818 | S106: =IFERROR(COUNTIFS(P_Dept,$B$106,P_Rating,">=4",P_Status,"Active")/COUNTIFS(M_Dept,$B$106,M_Status,"Active"),0) -> 0.40206186 | T106: =IFERROR(COUNTIFS(T_Dept,$B$106,T_Comp,"Compliant",T_Status,"Active")/COUNTIFS(M_Dept,$B$106,M_Status,"Active"),0) -> 0.89690722 | U106: =IFERROR(AVERAGEIFS(M_Tenure,M_Dept,$B$106,M_Status,"Active"),0) -> 2.7257732
B107: Operations | D107: =COUNTIFS(M_Dept,$B$107,M_Status,"Active") -> 77 | E107: =COUNTIFS(X_Dept,$B$107) -> 13 | F107: =IFERROR(COUNTIFS(X_Dept,$B$107)/((COUNTIFS(M_Dept,$B$107,M_DOJ,"<"&PeriodStart)+COUNTIFS(M_Dept,$B$107,M_Status,"Active"))/2),0) -> 0.17449664 | G107: =IFERROR(AVERAGEIFS(P_Rating,P_Dept,$B$107),0) -> 3.3444444 | H107: =COUNTIFS(P_Dept,$B$107,P_Elig,"Eligible") -> 16 | I107: =IFERROR(AVERAGEIFS(C_CTC,C_Dept,$B$107,C_Status,"Active")/100000,0) -> 13.135714 | J107: =IFERROR(AVERAGEIFS(C_Compa,C_Dept,$B$107,C_Status,"Active"),0) -> 0.83350649 | K107: =IFERROR(AVERAGEIFS(A_Att,A_Dept,$B$107,A_Status,"Active"),0) -> 0.89956698 | L107: =IFERROR(AVERAGEIFS(E_Overall,E_Dept,$B$107,E_Status,"Active"),0) -> 3.2798701 | M107: =IFERROR((COUNTIFS(E_Dept,$B$107,E_Cat,"Promoter",E_Status,"Active",E_Survey,"Yes")-COUNTIFS(E_Dept,$B$107,E_Cat,"Detractor",E_Status,"Active",E_Survey,"Yes"))/COUNTIFS(E_Dept,$B$107,E_Status,"Active",E_Survey,"Yes")*100,0) -> 23.809524 | N107: =COUNTIFS(E_Dept,$B$107,E_Risk,"High") -> 8 | O107: =COUNTIFS(R_Dept,$B$107,R_Status,"Open") -> 8 | P107: =IFERROR(AVERAGEIFS(R_TTF,R_Dept,$B$107,R_Status,"Filled"),0) -> 42 | Q107: =IFERROR(COUNTIFS(M_Dept,$B$107,M_Gender,"Female",M_Status,"Active")/COUNTIFS(M_Dept,$B$107,M_Status,"Active"),0) -> 0.31168831 | R107: =IFERROR(AVERAGEIFS(T_Hours,T_Dept,$B$107),0) -> 24.922222 | S107: =IFERROR(COUNTIFS(P_Dept,$B$107,P_Rating,">=4",P_Status,"Active")/COUNTIFS(M_Dept,$B$107,M_Status,"Active"),0) -> 0.41558442 | T107: =IFERROR(COUNTIFS(T_Dept,$B$107,T_Comp,"Compliant",T_Status,"Active")/COUNTIFS(M_Dept,$B$107,M_Status,"Active"),0) -> 0.85714286 | U107: =IFERROR(AVERAGEIFS(M_Tenure,M_Dept,$B$107,M_Status,"Active"),0) -> 2.8272727
B108: Customer Support | D108: =COUNTIFS(M_Dept,$B$108,M_Status,"Active") -> 61 | E108: =COUNTIFS(X_Dept,$B$108) -> 9 | F108: =IFERROR(COUNTIFS(X_Dept,$B$108)/((COUNTIFS(M_Dept,$B$108,M_DOJ,"<"&PeriodStart)+COUNTIFS(M_Dept,$B$108,M_Status,"Active"))/2),0) -> 0.15929204 | G108: =IFERROR(AVERAGEIFS(P_Rating,P_Dept,$B$108),0) -> 3.2285714 | H108: =COUNTIFS(P_Dept,$B$108,P_Elig,"Eligible") -> 13 | I108: =IFERROR(AVERAGEIFS(C_CTC,C_Dept,$B$108,C_Status,"Active")/100000,0) -> 12.293279 | J108: =IFERROR(AVERAGEIFS(C_Compa,C_Dept,$B$108,C_Status,"Active"),0) -> 0.73180328 | K108: =IFERROR(AVERAGEIFS(A_Att,A_Dept,$B$108,A_Status,"Active"),0) -> 0.8934168 | L108: =IFERROR(AVERAGEIFS(E_Overall,E_Dept,$B$108,E_Status,"Active"),0) -> 3.3244262 | M108: =IFERROR((COUNTIFS(E_Dept,$B$108,E_Cat,"Promoter",E_Status,"Active",E_Survey,"Yes")-COUNTIFS(E_Dept,$B$108,E_Cat,"Detractor",E_Status,"Active",E_Survey,"Yes"))/COUNTIFS(E_Dept,$B$108,E_Status,"Active",E_Survey,"Yes")*100,0) -> 31.372549 | N108: =COUNTIFS(E_Dept,$B$108,E_Risk,"High") -> 7 | O108: =COUNTIFS(R_Dept,$B$108,R_Status,"Open") -> 6 | P108: =IFERROR(AVERAGEIFS(R_TTF,R_Dept,$B$108,R_Status,"Filled"),0) -> 38.166667 | Q108: =IFERROR(COUNTIFS(M_Dept,$B$108,M_Gender,"Female",M_Status,"Active")/COUNTIFS(M_Dept,$B$108,M_Status,"Active"),0) -> 0.49180328 | R108: =IFERROR(AVERAGEIFS(T_Hours,T_Dept,$B$108),0) -> 27.771429 | S108: =IFERROR(COUNTIFS(P_Dept,$B$108,P_Rating,">=4",P_Status,"Active")/COUNTIFS(M_Dept,$B$108,M_Status,"Active"),0) -> 0.37704918 | T108: =IFERROR(COUNTIFS(T_Dept,$B$108,T_Comp,"Compliant",T_Status,"Active")/COUNTIFS(M_Dept,$B$108,M_Status,"Active"),0) -> 0.85245902 | U108: =IFERROR(AVERAGEIFS(M_Tenure,M_Dept,$B$108,M_Status,"Active"),0) -> 2.3278689
B109: Sales | D109: =COUNTIFS(M_Dept,$B$109,M_Status,"Active") -> 51 | E109: =COUNTIFS(X_Dept,$B$109) -> 9 | F109: =IFERROR(COUNTIFS(X_Dept,$B$109)/((COUNTIFS(M_Dept,$B$109,M_DOJ,"<"&PeriodStart)+COUNTIFS(M_Dept,$B$109,M_Status,"Active"))/2),0) -> 0.18556701 | G109: =IFERROR(AVERAGEIFS(P_Rating,P_Dept,$B$109),0) -> 3.1 | H109: =COUNTIFS(P_Dept,$B$109,P_Elig,"Eligible") -> 9 | I109: =IFERROR(AVERAGEIFS(C_CTC,C_Dept,$B$109,C_Status,"Active")/100000,0) -> 15.844902 | J109: =IFERROR(AVERAGEIFS(C_Compa,C_Dept,$B$109,C_Status,"Active"),0) -> 0.92980392 | K109: =IFERROR(AVERAGEIFS(A_Att,A_Dept,$B$109,A_Status,"Active"),0) -> 0.89352406 | L109: =IFERROR(AVERAGEIFS(E_Overall,E_Dept,$B$109,E_Status,"Active"),0) -> 3.2901961 | M109: =IFERROR((COUNTIFS(E_Dept,$B$109,E_Cat,"Promoter",E_Status,"Active",E_Survey,"Yes")-COUNTIFS(E_Dept,$B$109,E_Cat,"Detractor",E_Status,"Active",E_Survey,"Yes"))/COUNTIFS(E_Dept,$B$109,E_Status,"Active",E_Survey,"Yes")*100,0) -> 18.604651 | N109: =COUNTIFS(E_Dept,$B$109,E_Risk,"High") -> 4 | O109: =COUNTIFS(R_Dept,$B$109,R_Status,"Open") -> 4 | P109: =IFERROR(AVERAGEIFS(R_TTF,R_Dept,$B$109,R_Status,"Filled"),0) -> 42.2 | Q109: =IFERROR(COUNTIFS(M_Dept,$B$109,M_Gender,"Female",M_Status,"Active")/COUNTIFS(M_Dept,$B$109,M_Status,"Active"),0) -> 0.47058824 | R109: =IFERROR(AVERAGEIFS(T_Hours,T_Dept,$B$109),0) -> 25.033333 | S109: =IFERROR(COUNTIFS(P_Dept,$B$109,P_Rating,">=4",P_Status,"Active")/COUNTIFS(M_Dept,$B$109,M_Status,"Active"),0) -> 0.39215686 | T109: =IFERROR(COUNTIFS(T_Dept,$B$109,T_Comp,"Compliant",T_Status,"Active")/COUNTIFS(M_Dept,$B$109,M_Status,"Active"),0) -> 0.88235294 | U109: =IFERROR(AVERAGEIFS(M_Tenure,M_Dept,$B$109,M_Status,"Active"),0) -> 2.6705882
B110: Product | D110: =COUNTIFS(M_Dept,$B$110,M_Status,"Active") -> 33 | E110: =COUNTIFS(X_Dept,$B$110) -> 2 | F110: =IFERROR(COUNTIFS(X_Dept,$B$110)/((COUNTIFS(M_Dept,$B$110,M_DOJ,"<"&PeriodStart)+COUNTIFS(M_Dept,$B$110,M_Status,"Active"))/2),0) -> 0.074074074 | G110: =IFERROR(AVERAGEIFS(P_Rating,P_Dept,$B$110),0) -> 3.3714286 | H110: =COUNTIFS(P_Dept,$B$110,P_Elig,"Eligible") -> 7 | I110: =IFERROR(AVERAGEIFS(C_CTC,C_Dept,$B$110,C_Status,"Active")/100000,0) -> 19.370909 | J110: =IFERROR(AVERAGEIFS(C_Compa,C_Dept,$B$110,C_Status,"Active"),0) -> 1.1133333 | K110: =IFERROR(AVERAGEIFS(A_Att,A_Dept,$B$110,A_Status,"Active"),0) -> 0.87303214 | L110: =IFERROR(AVERAGEIFS(E_Overall,E_Dept,$B$110,E_Status,"Active"),0) -> 3.2675758 | M110: =IFERROR((COUNTIFS(E_Dept,$B$110,E_Cat,"Promoter",E_Status,"Active",E_Survey,"Yes")-COUNTIFS(E_Dept,$B$110,E_Cat,"Detractor",E_Status,"Active",E_Survey,"Yes"))/COUNTIFS(E_Dept,$B$110,E_Status,"Active",E_Survey,"Yes")*100,0) -> 27.586207 | N110: =COUNTIFS(E_Dept,$B$110,E_Risk,"High") -> 0 | O110: =COUNTIFS(R_Dept,$B$110,R_Status,"Open") -> 3 | P110: =IFERROR(AVERAGEIFS(R_TTF,R_Dept,$B$110,R_Status,"Filled"),0) -> 49.166667 | Q110: =IFERROR(COUNTIFS(M_Dept,$B$110,M_Gender,"Female",M_Status,"Active")/COUNTIFS(M_Dept,$B$110,M_Status,"Active"),0) -> 0.48484848 | R110: =IFERROR(AVERAGEIFS(T_Hours,T_Dept,$B$110),0) -> 25.971429 | S110: =IFERROR(COUNTIFS(P_Dept,$B$110,P_Rating,">=4",P_Status,"Active")/COUNTIFS(M_Dept,$B$110,M_Status,"Active"),0) -> 0.42424242 | T110: =IFERROR(COUNTIFS(T_Dept,$B$110,T_Comp,"Compliant",T_Status,"Active")/COUNTIFS(M_Dept,$B$110,M_Status,"Active"),0) -> 0.81818182 | U110: =IFERROR(AVERAGEIFS(M_Tenure,M_Dept,$B$110,M_Status,"Active"),0) -> 2.230303
B111: Marketing | D111: =COUNTIFS(M_Dept,$B$111,M_Status,"Active") -> 27 | E111: =COUNTIFS(X_Dept,$B$111) -> 3 | F111: =IFERROR(COUNTIFS(X_Dept,$B$111)/((COUNTIFS(M_Dept,$B$111,M_DOJ,"<"&PeriodStart)+COUNTIFS(M_Dept,$B$111,M_Status,"Active"))/2),0) -> 0.11764706 | G111: =IFERROR(AVERAGEIFS(P_Rating,P_Dept,$B$111),0) -> 3.0666667 | H111: =COUNTIFS(P_Dept,$B$111,P_Elig,"Eligible") -> 3 | I111: =IFERROR(AVERAGEIFS(C_CTC,C_Dept,$B$111,C_Status,"Active")/100000,0) -> 15.875185 | J111: =IFERROR(AVERAGEIFS(C_Compa,C_Dept,$B$111,C_Status,"Active"),0) -> 0.93037037 | K111: =IFERROR(AVERAGEIFS(A_Att,A_Dept,$B$111,A_Status,"Active"),0) -> 0.90353846 | L111: =IFERROR(AVERAGEIFS(E_Overall,E_Dept,$B$111,E_Status,"Active"),0) -> 3.2148148 | M111: =IFERROR((COUNTIFS(E_Dept,$B$111,E_Cat,"Promoter",E_Status,"Active",E_Survey,"Yes")-COUNTIFS(E_Dept,$B$111,E_Cat,"Detractor",E_Status,"Active",E_Survey,"Yes"))/COUNTIFS(E_Dept,$B$111,E_Status,"Active",E_Survey,"Yes")*100,0) -> 19.230769 | N111: =COUNTIFS(E_Dept,$B$111,E_Risk,"High") -> 1 | O111: =COUNTIFS(R_Dept,$B$111,R_Status,"Open") -> 4 | P111: =IFERROR(AVERAGEIFS(R_TTF,R_Dept,$B$111,R_Status,"Filled"),0) -> 40.428571 | Q111: =IFERROR(COUNTIFS(M_Dept,$B$111,M_Gender,"Female",M_Status,"Active")/COUNTIFS(M_Dept,$B$111,M_Status,"Active"),0) -> 0.51851852 | R111: =IFERROR(AVERAGEIFS(T_Hours,T_Dept,$B$111),0) -> 30.2 | S111: =IFERROR(COUNTIFS(P_Dept,$B$111,P_Rating,">=4",P_Status,"Active")/COUNTIFS(M_Dept,$B$111,M_Status,"Active"),0) -> 0.2962963 | T111: =IFERROR(COUNTIFS(T_Dept,$B$111,T_Comp,"Compliant",T_Status,"Active")/COUNTIFS(M_Dept,$B$111,M_Status,"Active"),0) -> 0.92592593 | U111: =IFERROR(AVERAGEIFS(M_Tenure,M_Dept,$B$111,M_Status,"Active"),0) -> 2.4925926
B112: Data & Analytics | D112: =COUNTIFS(M_Dept,$B$112,M_Status,"Active") -> 23 | E112: =COUNTIFS(X_Dept,$B$112) -> 7 | F112: =IFERROR(COUNTIFS(X_Dept,$B$112)/((COUNTIFS(M_Dept,$B$112,M_DOJ,"<"&PeriodStart)+COUNTIFS(M_Dept,$B$112,M_Status,"Active"))/2),0) -> 0.29787234 | G112: =IFERROR(AVERAGEIFS(P_Rating,P_Dept,$B$112),0) -> 3.2333333 | H112: =COUNTIFS(P_Dept,$B$112,P_Elig,"Eligible") -> 5 | I112: =IFERROR(AVERAGEIFS(C_CTC,C_Dept,$B$112,C_Status,"Active")/100000,0) -> 20.20087 | J112: =IFERROR(AVERAGEIFS(C_Compa,C_Dept,$B$112,C_Status,"Active"),0) -> 1.1282609 | K112: =IFERROR(AVERAGEIFS(A_Att,A_Dept,$B$112,A_Status,"Active"),0) -> 0.91148953 | L112: =IFERROR(AVERAGEIFS(E_Overall,E_Dept,$B$112,E_Status,"Active"),0) -> 3.3030435 | M112: =IFERROR((COUNTIFS(E_Dept,$B$112,E_Cat,"Promoter",E_Status,"Active",E_Survey,"Yes")-COUNTIFS(E_Dept,$B$112,E_Cat,"Detractor",E_Status,"Active",E_Survey,"Yes"))/COUNTIFS(E_Dept,$B$112,E_Status,"Active",E_Survey,"Yes")*100,0) -> 40 | N112: =COUNTIFS(E_Dept,$B$112,E_Risk,"High") -> 1 | O112: =COUNTIFS(R_Dept,$B$112,R_Status,"Open") -> 3 | P112: =IFERROR(AVERAGEIFS(R_TTF,R_Dept,$B$112,R_Status,"Filled"),0) -> 44 | Q112: =IFERROR(COUNTIFS(M_Dept,$B$112,M_Gender,"Female",M_Status,"Active")/COUNTIFS(M_Dept,$B$112,M_Status,"Active"),0) -> 0.47826087 | R112: =IFERROR(AVERAGEIFS(T_Hours,T_Dept,$B$112),0) -> 38.7 | S112: =IFERROR(COUNTIFS(P_Dept,$B$112,P_Rating,">=4",P_Status,"Active")/COUNTIFS(M_Dept,$B$112,M_Status,"Active"),0) -> 0.39130435 | T112: =IFERROR(COUNTIFS(T_Dept,$B$112,T_Comp,"Compliant",T_Status,"Active")/COUNTIFS(M_Dept,$B$112,M_Status,"Active"),0) -> 0.82608696 | U112: =IFERROR(AVERAGEIFS(M_Tenure,M_Dept,$B$112,M_Status,"Active"),0) -> 2.7130435
B113: Finance | D113: =COUNTIFS(M_Dept,$B$113,M_Status,"Active") -> 22 | E113: =COUNTIFS(X_Dept,$B$113) -> 3 | F113: =IFERROR(COUNTIFS(X_Dept,$B$113)/((COUNTIFS(M_Dept,$B$113,M_DOJ,"<"&PeriodStart)+COUNTIFS(M_Dept,$B$113,M_Status,"Active"))/2),0) -> 0.14285714 | G113: =IFERROR(AVERAGEIFS(P_Rating,P_Dept,$B$113),0) -> 3.52 | H113: =COUNTIFS(P_Dept,$B$113,P_Elig,"Eligible") -> 6 | I113: =IFERROR(AVERAGEIFS(C_CTC,C_Dept,$B$113,C_Status,"Active")/100000,0) -> 19.805909 | J113: =IFERROR(AVERAGEIFS(C_Compa,C_Dept,$B$113,C_Status,"Active"),0) -> 0.99636364 | K113: =IFERROR(AVERAGEIFS(A_Att,A_Dept,$B$113,A_Status,"Active"),0) -> 0.89310766 | L113: =IFERROR(AVERAGEIFS(E_Overall,E_Dept,$B$113,E_Status,"Active"),0) -> 3.1359091 | M113: =IFERROR((COUNTIFS(E_Dept,$B$113,E_Cat,"Promoter",E_Status,"Active",E_Survey,"Yes")-COUNTIFS(E_Dept,$B$113,E_Cat,"Detractor",E_Status,"Active",E_Survey,"Yes"))/COUNTIFS(E_Dept,$B$113,E_Status,"Active",E_Survey,"Yes")*100,0) -> 25 | N113: =COUNTIFS(E_Dept,$B$113,E_Risk,"High") -> 2 | O113: =COUNTIFS(R_Dept,$B$113,R_Status,"Open") -> 2 | P113: =IFERROR(AVERAGEIFS(R_TTF,R_Dept,$B$113,R_Status,"Filled"),0) -> 32 | Q113: =IFERROR(COUNTIFS(M_Dept,$B$113,M_Gender,"Female",M_Status,"Active")/COUNTIFS(M_Dept,$B$113,M_Status,"Active"),0) -> 0.63636364 | R113: =IFERROR(AVERAGEIFS(T_Hours,T_Dept,$B$113),0) -> 30.48 | S113: =IFERROR(COUNTIFS(P_Dept,$B$113,P_Rating,">=4",P_Status,"Active")/COUNTIFS(M_Dept,$B$113,M_Status,"Active"),0) -> 0.5 | T113: =IFERROR(COUNTIFS(T_Dept,$B$113,T_Comp,"Compliant",T_Status,"Active")/COUNTIFS(M_Dept,$B$113,M_Status,"Active"),0) -> 0.77272727 | U113: =IFERROR(AVERAGEIFS(M_Tenure,M_Dept,$B$113,M_Status,"Active"),0) -> 2.7727273
B114: Human Resources | D114: =COUNTIFS(M_Dept,$B$114,M_Status,"Active") -> 22 | E114: =COUNTIFS(X_Dept,$B$114) -> 3 | F114: =IFERROR(COUNTIFS(X_Dept,$B$114)/((COUNTIFS(M_Dept,$B$114,M_DOJ,"<"&PeriodStart)+COUNTIFS(M_Dept,$B$114,M_Status,"Active"))/2),0) -> 0.14285714 | G114: =IFERROR(AVERAGEIFS(P_Rating,P_Dept,$B$114),0) -> 3.08 | H114: =COUNTIFS(P_Dept,$B$114,P_Elig,"Eligible") -> 4 | I114: =IFERROR(AVERAGEIFS(C_CTC,C_Dept,$B$114,C_Status,"Active")/100000,0) -> 17.519545 | J114: =IFERROR(AVERAGEIFS(C_Compa,C_Dept,$B$114,C_Status,"Active"),0) -> 0.91772727 | K114: =IFERROR(AVERAGEIFS(A_Att,A_Dept,$B$114,A_Status,"Active"),0) -> 0.89434223 | L114: =IFERROR(AVERAGEIFS(E_Overall,E_Dept,$B$114,E_Status,"Active"),0) -> 3.1522727 | M114: =IFERROR((COUNTIFS(E_Dept,$B$114,E_Cat,"Promoter",E_Status,"Active",E_Survey,"Yes")-COUNTIFS(E_Dept,$B$114,E_Cat,"Detractor",E_Status,"Active",E_Survey,"Yes"))/COUNTIFS(E_Dept,$B$114,E_Status,"Active",E_Survey,"Yes")*100,0) -> 43.75 | N114: =COUNTIFS(E_Dept,$B$114,E_Risk,"High") -> 1 | O114: =COUNTIFS(R_Dept,$B$114,R_Status,"Open") -> 1 | P114: =IFERROR(AVERAGEIFS(R_TTF,R_Dept,$B$114,R_Status,"Filled"),0) -> 17.5 | Q114: =IFERROR(COUNTIFS(M_Dept,$B$114,M_Gender,"Female",M_Status,"Active")/COUNTIFS(M_Dept,$B$114,M_Status,"Active"),0) -> 0.5 | R114: =IFERROR(AVERAGEIFS(T_Hours,T_Dept,$B$114),0) -> 30.08 | S114: =IFERROR(COUNTIFS(P_Dept,$B$114,P_Rating,">=4",P_Status,"Active")/COUNTIFS(M_Dept,$B$114,M_Status,"Active"),0) -> 0.36363636 | T114: =IFERROR(COUNTIFS(T_Dept,$B$114,T_Comp,"Compliant",T_Status,"Active")/COUNTIFS(M_Dept,$B$114,M_Status,"Active"),0) -> 0.86363636 | U114: =IFERROR(AVERAGEIFS(M_Tenure,M_Dept,$B$114,M_Status,"Active"),0) -> 3.5818182
B115: Legal & Compliance | D115: =COUNTIFS(M_Dept,$B$115,M_Status,"Active") -> 23 | E115: =COUNTIFS(X_Dept,$B$115) -> 2 | F115: =IFERROR(COUNTIFS(X_Dept,$B$115)/((COUNTIFS(M_Dept,$B$115,M_DOJ,"<"&PeriodStart)+COUNTIFS(M_Dept,$B$115,M_Status,"Active"))/2),0) -> 0.10526316 | G115: =IFERROR(AVERAGEIFS(P_Rating,P_Dept,$B$115),0) -> 2.84 | H115: =COUNTIFS(P_Dept,$B$115,P_Elig,"Eligible") -> 5 | I115: =IFERROR(AVERAGEIFS(C_CTC,C_Dept,$B$115,C_Status,"Active")/100000,0) -> 20.036957 | J115: =IFERROR(AVERAGEIFS(C_Compa,C_Dept,$B$115,C_Status,"Active"),0) -> 1.0243478 | K115: =IFERROR(AVERAGEIFS(A_Att,A_Dept,$B$115,A_Status,"Active"),0) -> 0.83914227 | L115: =IFERROR(AVERAGEIFS(E_Overall,E_Dept,$B$115,E_Status,"Active"),0) -> 3.1143478 | M115: =IFERROR((COUNTIFS(E_Dept,$B$115,E_Cat,"Promoter",E_Status,"Active",E_Survey,"Yes")-COUNTIFS(E_Dept,$B$115,E_Cat,"Detractor",E_Status,"Active",E_Survey,"Yes"))/COUNTIFS(E_Dept,$B$115,E_Status,"Active",E_Survey,"Yes")*100,0) -> -4.7619048 | N115: =COUNTIFS(E_Dept,$B$115,E_Risk,"High") -> 0 | O115: =COUNTIFS(R_Dept,$B$115,R_Status,"Open") -> 4 | P115: =IFERROR(AVERAGEIFS(R_TTF,R_Dept,$B$115,R_Status,"Filled"),0) -> 52.8 | Q115: =IFERROR(COUNTIFS(M_Dept,$B$115,M_Gender,"Female",M_Status,"Active")/COUNTIFS(M_Dept,$B$115,M_Status,"Active"),0) -> 0.69565217 | R115: =IFERROR(AVERAGEIFS(T_Hours,T_Dept,$B$115),0) -> 25.96 | S115: =IFERROR(COUNTIFS(P_Dept,$B$115,P_Rating,">=4",P_Status,"Active")/COUNTIFS(M_Dept,$B$115,M_Status,"Active"),0) -> 0.30434783 | T115: =IFERROR(COUNTIFS(T_Dept,$B$115,T_Comp,"Compliant",T_Status,"Active")/COUNTIFS(M_Dept,$B$115,M_Status,"Active"),0) -> 0.95652174 | U115: =IFERROR(AVERAGEIFS(M_Tenure,M_Dept,$B$115,M_Status,"Active"),0) -> 1.9043478
...

Sheet Employee_Explorer
A1: EMPLOYEE EXPLORER
A2: =" Every employee in: "&SelLabel&" · "&COUNT(Calc_Engine!$H$2:$H$501)&" people · change the department on the Dashboard to switch the list" -> Every employee in: All Departments · 500 people · change the department on the Dashboard to switch the list
A3: Rows highlighted yellow = the employee selected on the Dashboard. Use the filter arrows to sort or slice this list.
A4: # | B4: Emp ID | C4: Employee Name | D4: Designation | E4: Department | F4: Level | G4: Manager | H4: Status | I4: Tenure (Yrs) | J4: Rating | K4: 9-Box | L4: Promotion | M4: CTC (₹ L) | N4: Compa | O4: Attendance | P4: Engagement | Q4: Flight Risk | R4: row
A5: =IF(B5="","",1) -> 1 | B5: =IF(Calc_Engine!I2="","",Calc_Engine!I2) -> EMP1001 | C5: =IF($R5="","",INDEX(M_Name,$R5)) -> Vidya Kulkarni | D5: =IF($R5="","",INDEX(M_Title,$R5)) -> Head of People | E5: =IF($R5="","",INDEX(M_Dept,$R5)) -> Human Resources | F5: =IF($R5="","",INDEX(M_Level,$R5)) -> L7 | G5: =IF($R5="","",INDEX(M_Mgr,$R5)) -> Arvind Rao (CEO) | H5: =IF($R5="","",INDEX(M_Status,$R5)) -> Active | I5: =IF($R5="","",INDEX(M_Tenure,$R5)) -> 9.8 | J5: =IF($R5="","",INDEX(P_Rating,$R5)) -> 5 | K5: =IF($R5="","",INDEX(P_9Box,$R5)) -> Star | L5: =IF($R5="","",INDEX(P_Elig,$R5)) -> Not Eligible | M5: =IF($R5="","",INDEX(C_CTC,$R5)/100000) -> 76.32 | N5: =IF($R5="","",INDEX(C_Compa,$R5)) -> 0.93 | O5: =IF($R5="","",INDEX(A_Att,$R5)) -> 0.928 | P5: =IF($R5="","",INDEX(E_Overall,$R5)) -> 3.73 | Q5: =IF($R5="","",INDEX(E_Risk,$R5)) -> Low | R5: =IF(B5="","",MATCH(B5,M_ID,0)) -> 1
A6: =IF(B6="","",2) -> 2 | B6: =IF(Calc_Engine!I3="","",Calc_Engine!I3) -> EMP1002 | C6: =IF($R6="","",INDEX(M_Name,$R6)) -> Vikas Singh | D6: =IF($R6="","",INDEX(M_Title,$R6)) -> Engineering Manager | E6: =IF($R6="","",INDEX(M_Dept,$R6)) -> Engineering | F6: =IF($R6="","",INDEX(M_Level,$R6)) -> L5 | G6: =IF($R6="","",INDEX(M_Mgr,$R6)) -> Yamini Nair | H6: =IF($R6="","",INDEX(M_Status,$R6)) -> Active | I6: =IF($R6="","",INDEX(M_Tenure,$R6)) -> 7.9 | J6: =IF($R6="","",INDEX(P_Rating,$R6)) -> 4 | K6: =IF($R6="","",INDEX(P_9Box,$R6)) -> High Performer | L6: =IF($R6="","",INDEX(P_Elig,$R6)) -> Eligible | M6: =IF($R6="","",INDEX(C_CTC,$R6)/100000) -> 44.07 | N6: =IF($R6="","",INDEX(C_Compa,$R6)) -> 1.2 | O6: =IF($R6="","",INDEX(A_Att,$R6)) -> 0.96 | P6: =IF($R6="","",INDEX(E_Overall,$R6)) -> 4.53 | Q6: =IF($R6="","",INDEX(E_Risk,$R6)) -> Low | R6: =IF(B6="","",MATCH(B6,M_ID,0)) -> 2
A7: =IF(B7="","",3) -> 3 | B7: =IF(Calc_Engine!I4="","",Calc_Engine!I4) -> EMP1003 | C7: =IF($R7="","",INDEX(M_Name,$R7)) -> Prakash Das | D7: =IF($R7="","",INDEX(M_Title,$R7)) -> Senior HR Manager | E7: =IF($R7="","",INDEX(M_Dept,$R7)) -> Human Resources | F7: =IF($R7="","",INDEX(M_Level,$R7)) -> L6 | G7: =IF($R7="","",INDEX(M_Mgr,$R7)) -> Vidya Kulkarni | H7: =IF($R7="","",INDEX(M_Status,$R7)) -> Active | I7: =IF($R7="","",INDEX(M_Tenure,$R7)) -> 7.5 | J7: =IF($R7="","",INDEX(P_Rating,$R7)) -> 2 | K7: =IF($R7="","",INDEX(P_9Box,$R7)) -> Inconsistent Player | L7: =IF($R7="","",INDEX(P_Elig,$R7)) -> Not Eligible | M7: =IF($R7="","",INDEX(C_CTC,$R7)/100000) -> 51.06 | N7: =IF($R7="","",INDEX(C_Compa,$R7)) -> 0.95 | O7: =IF($R7="","",INDEX(A_Att,$R7)) -> 0.932 | P7: =IF($R7="","",INDEX(E_Overall,$R7)) -> 3.23 | Q7: =IF($R7="","",INDEX(E_Risk,$R7)) -> Low | R7: =IF(B7="","",MATCH(B7,M_ID,0)) -> 3
A8: =IF(B8="","",4) -> 4 | B8: =IF(Calc_Engine!I5="","",Calc_Engine!I5) -> EMP1004 | C8: =IF($R8="","",INDEX(M_Name,$R8)) -> Fatima Choudhary | D8: =IF($R8="","",INDEX(M_Title,$R8)) -> Engineering Manager | E8: =IF($R8="","",INDEX(M_Dept,$R8)) -> Engineering | F8: =IF($R8="","",INDEX(M_Level,$R8)) -> L5 | G8: =IF($R8="","",INDEX(M_Mgr,$R8)) -> Yamini Nair | H8: =IF($R8="","",INDEX(M_Status,$R8)) -> Active | I8: =IF($R8="","",INDEX(M_Tenure,$R8)) -> 7.5 | J8: =IF($R8="","",INDEX(P_Rating,$R8)) -> 2 | K8: =IF($R8="","",INDEX(P_9Box,$R8)) -> Inconsistent Player | L8: =IF($R8="","",INDEX(P_Elig,$R8)) -> Not Eligible | M8: =IF($R8="","",INDEX(C_CTC,$R8)/100000) -> 44.89 | N8: =IF($R8="","",INDEX(C_Compa,$R8)) -> 1.22 | O8: =IF($R8="","",INDEX(A_Att,$R8)) -> 0.88 | P8: =IF($R8="","",INDEX(E_Overall,$R8)) -> 3.12 | Q8: =IF($R8="","",INDEX(E_Risk,$R8)) -> Low | R8: =IF(B8="","",MATCH(B8,M_ID,0)) -> 4
A9: =IF(B9="","",5) -> 5 | B9: =IF(Calc_Engine!I6="","",Calc_Engine!I6) -> EMP1005 | C9: =IF($R9="","",INDEX(M_Name,$R9)) -> Gaurav Fernandes | D9: =IF($R9="","",INDEX(M_Title,$R9)) -> Engineering Manager | E9: =IF($R9="","",INDEX(M_Dept,$R9)) -> Engineering | F9: =IF($R9="","",INDEX(M_Level,$R9)) -> L5 | G9: =IF($R9="","",INDEX(M_Mgr,$R9)) -> Yamini Nair | H9: =IF($R9="","",INDEX(M_Status,$R9)) -> Active | I9: =IF($R9="","",INDEX(M_Tenure,$R9)) -> 7.2 | J9: =IF($R9="","",INDEX(P_Rating,$R9)) -> 3 | K9: =IF($R9="","",INDEX(P_9Box,$R9)) -> Core Player | L9: =IF($R9="","",INDEX(P_Elig,$R9)) -> Not Eligible | M9: =IF($R9="","",INDEX(C_CTC,$R9)/100000) -> 49.38 | N9: =IF($R9="","",INDEX(C_Compa,$R9)) -> 1.35 | O9: =IF($R9="","",INDEX(A_Att,$R9)) -> 0.94 | P9: =IF($R9="","",INDEX(E_Overall,$R9)) -> 3.82 | Q9: =IF($R9="","",INDEX(E_Risk,$R9)) -> Low | R9: =IF(B9="","",MATCH(B9,M_ID,0)) -> 5
A10: =IF(B10="","",6) -> 6 | B10: =IF(Calc_Engine!I7="","",Calc_Engine!I7) -> EMP1006 | C10: =IF($R10="","",INDEX(M_Name,$R10)) -> Yash Shah | D10: =IF($R10="","",INDEX(M_Title,$R10)) -> Operations Manager | E10: =IF($R10="","",INDEX(M_Dept,$R10)) -> Operations | F10: =IF($R10="","",INDEX(M_Level,$R10)) -> L5 | G10: =IF($R10="","",INDEX(M_Mgr,$R10)) -> Pallavi Shah | H10: =IF($R10="","",INDEX(M_Status,$R10)) -> Exited | I10: =IF($R10="","",INDEX(M_Tenure,$R10)) -> 7 | J10: =IF($R10="","",INDEX(P_Rating,$R10)) -> 4 | K10: =IF($R10="","",INDEX(P_9Box,$R10)) -> High Performer | L10: =IF($R10="","",INDEX(P_Elig,$R10)) -> Not Eligible | M10: =IF($R10="","",INDEX(C_CTC,$R10)/100000) -> 27.14 | N10: =IF($R10="","",INDEX(C_Compa,$R10)) -> 0.74 | O10: =IF($R10="","",INDEX(A_Att,$R10)) -> 0.90047393 | P10: =IF($R10="","",INDEX(E_Overall,$R10)) -> 2.97 | Q10: =IF($R10="","",INDEX(E_Risk,$R10)) -> Exited | R10: =IF(B10="","",MATCH(B10,M_ID,0)) -> 6
A11: =IF(B11="","",7) -> 7 | B11: =IF(Calc_Engine!I8="","",Calc_Engine!I8) -> EMP1007 | C11: =IF($R11="","",INDEX(M_Name,$R11)) -> Imran Tiwari | D11: =IF($R11="","",INDEX(M_Title,$R11)) -> Marketing Lead | E11: =IF($R11="","",INDEX(M_Dept,$R11)) -> Marketing | F11: =IF($R11="","",INDEX(M_Level,$R11)) -> L4 | G11: =IF($R11="","",INDEX(M_Mgr,$R11)) -> Nandini Iyer | H11: =IF($R11="","",INDEX(M_Status,$R11)) -> Exited | I11: =IF($R11="","",INDEX(M_Tenure,$R11)) -> 6.4 | J11: =IF($R11="","",INDEX(P_Rating,$R11)) -> 1 | K11: =IF($R11="","",INDEX(P_9Box,$R11)) -> Underperformer | L11: =IF($R11="","",INDEX(P_Elig,$R11)) -> Not Eligible | M11: =IF($R11="","",INDEX(C_CTC,$R11)/100000) -> 22.29 | N11: =IF($R11="","",INDEX(C_Compa,$R11)) -> 0.95 | O11: =IF($R11="","",INDEX(A_Att,$R11)) -> 0.78448276 | P11: =IF($R11="","",INDEX(E_Overall,$R11)) -> 2.43 | Q11: =IF($R11="","",INDEX(E_Risk,$R11)) -> Exited | R11: =IF(B11="","",MATCH(B11,M_ID,0)) -> 7
A12: =IF(B12="","",8) -> 8 | B12: =IF(Calc_Engine!I9="","",Calc_Engine!I9) -> EMP1008 | C12: =IF($R12="","",INDEX(M_Name,$R12)) -> Aishwarya Khan | D12: =IF($R12="","",INDEX(M_Title,$R12)) -> Head of Engineering | E12: =IF($R12="","",INDEX(M_Dept,$R12)) -> Engineering | F12: =IF($R12="","",INDEX(M_Level,$R12)) -> L7 | G12: =IF($R12="","",INDEX(M_Mgr,$R12)) -> Arvind Rao (CEO) | H12: =IF($R12="","",INDEX(M_Status,$R12)) -> Active | I12: =IF($R12="","",INDEX(M_Tenure,$R12)) -> 6.9 | J12: =IF($R12="","",INDEX(P_Rating,$R12)) -> 3 | K12: =IF($R12="","",INDEX(P_9Box,$R12)) -> Core Player | L12: =IF($R12="","",INDEX(P_Elig,$R12)) -> Not Eligible | M12: =IF($R12="","",INDEX(C_CTC,$R12)/100000) -> 92.08 | N12: =IF($R12="","",INDEX(C_Compa,$R12)) -> 1.12 | O12: =IF($R12="","",INDEX(A_Att,$R12)) -> 0.944 | P12: =IF($R12="","",INDEX(E_Overall,$R12)) -> 2.03 | Q12: =IF($R12="","",INDEX(E_Risk,$R12)) -> Low | R12: =IF(B12="","",MATCH(B12,M_ID,0)) -> 8
A13: =IF(B13="","",9) -> 9 | B13: =IF(Calc_Engine!I10="","",Calc_Engine!I10) -> EMP1009 | C13: =IF($R13="","",INDEX(M_Name,$R13)) -> Ankit Khanna | D13: =IF($R13="","",INDEX(M_Title,$R13)) -> Operations Manager | E13: =IF($R13="","",INDEX(M_Dept,$R13)) -> Operations | F13: =IF($R13="","",INDEX(M_Level,$R13)) -> L5 | G13: =IF($R13="","",INDEX(M_Mgr,$R13)) -> Imran Mishra | H13: =IF($R13="","",INDEX(M_Status,$R13)) -> Active | I13: =IF($R13="","",INDEX(M_Tenure,$R13)) -> 6.9 | J13: =IF($R13="","",INDEX(P_Rating,$R13)) -> 3 | K13: =IF($R13="","",INDEX(P_9Box,$R13)) -> Core Player | L13: =IF($R13="","",INDEX(P_Elig,$R13)) -> Not Eligible | M13: =IF($R13="","",INDEX(C_CTC,$R13)/100000) -> 36.08 | N13: =IF($R13="","",INDEX(C_Compa,$R13)) -> 0.98 | O13: =IF($R13="","",INDEX(A_Att,$R13)) -> 0.944 | P13: =IF($R13="","",INDEX(E_Overall,$R13)) -> 3.2 | Q13: =IF($R13="","",INDEX(E_Risk,$R13)) -> Low | R13: =IF(B13="","",MATCH(B13,M_ID,0)) -> 9
A14: =IF(B14="","",10) -> 10 | B14: =IF(Calc_Engine!I11="","",Calc_Engine!I11) -> EMP1010 | C14: =IF($R14="","",INDEX(M_Name,$R14)) -> Pooja Das | D14: =IF($R14="","",INDEX(M_Title,$R14)) -> Head of Finance | E14: =IF($R14="","",INDEX(M_Dept,$R14)) -> Finance | F14: =IF($R14="","",INDEX(M_Level,$R14)) -> L7 | G14: =IF($R14="","",INDEX(M_Mgr,$R14)) -> Arvind Rao (CEO) | H14: =IF($R14="","",INDEX(M_Status,$R14)) -> Active | I14: =IF($R14="","",INDEX(M_Tenure,$R14)) -> 6.9 | J14: =IF($R14="","",INDEX(P_Rating,$R14)) -> 2 | K14: =IF($R14="","",INDEX(P_9Box,$R14)) -> Inconsistent Player | L14: =IF($R14="","",INDEX(P_Elig,$R14)) -> Not Eligible | M14: =IF($R14="","",INDEX(C_CTC,$R14)/100000) -> 81.36 | N14: =IF($R14="","",INDEX(C_Compa,$R14)) -> 0.99 | O14: =IF($R14="","",INDEX(A_Att,$R14)) -> 0.912 | P14: =IF($R14="","",INDEX(E_Overall,$R14)) -> 3.4 | Q14: =IF($R14="","",INDEX(E_Risk,$R14)) -> Low | R14: =IF(B14="","",MATCH(B14,M_ID,0)) -> 10
A15: =IF(B15="","",11) -> 11 | B15: =IF(Calc_Engine!I12="","",Calc_Engine!I12) -> EMP1011 | C15: =IF($R15="","",INDEX(M_Name,$R15)) -> Trisha Patel | D15: =IF($R15="","",INDEX(M_Title,$R15)) -> Principal Product Manager | E15: =IF($R15="","",INDEX(M_Dept,$R15)) -> Product | F15: =IF($R15="","",INDEX(M_Level,$R15)) -> L6 | G15: =IF($R15="","",INDEX(M_Mgr,$R15)) -> Dev Bose | H15: =IF($R15="","",INDEX(M_Status,$R15)) -> Active | I15: =IF($R15="","",INDEX(M_Tenure,$R15)) -> 6.8 | J15: =IF($R15="","",INDEX(P_Rating,$R15)) -> 3 | K15: =IF($R15="","",INDEX(P_9Box,$R15)) -> Core Player | L15: =IF($R15="","",INDEX(P_Elig,$R15)) -> Not Eligible | M15: =IF($R15="","",INDEX(C_CTC,$R15)/100000) -> 56.57 | N15: =IF($R15="","",INDEX(C_Compa,$R15)) -> 1.05 | O15: =IF($R15="","",INDEX(A_Att,$R15)) -> 0.892 | P15: =IF($R15="","",INDEX(E_Overall,$R15)) -> 2.9 | Q15: =IF($R15="","",INDEX(E_Risk,$R15)) -> Medium | R15: =IF(B15="","",MATCH(B15,M_ID,0)) -> 11
A16: =IF(B16="","",12) -> 12 | B16: =IF(Calc_Engine!I13="","",Calc_Engine!I13) -> EMP1012 | C16: =IF($R16="","",INDEX(M_Name,$R16)) -> Krishna Kumar | D16: =IF($R16="","",INDEX(M_Title,$R16)) -> Operations Lead | E16: =IF($R16="","",INDEX(M_Dept,$R16)) -> Operations | F16: =IF($R16="","",INDEX(M_Level,$R16)) -> L4 | G16: =IF($R16="","",INDEX(M_Mgr,$R16)) -> Amit Kumar | H16: =IF($R16="","",INDEX(M_Status,$R16)) -> Active | I16: =IF($R16="","",INDEX(M_Tenure,$R16)) -> 6.8 | J16: =IF($R16="","",INDEX(P_Rating,$R16)) -> 3 | K16: =IF($R16="","",INDEX(P_9Box,$R16)) -> Core Player | L16: =IF($R16="","",INDEX(P_Elig,$R16)) -> Not Eligible | M16: =IF($R16="","",INDEX(C_CTC,$R16)/100000) -> 17.21 | N16: =IF($R16="","",INDEX(C_Compa,$R16)) -> 0.73 | O16: =IF($R16="","",INDEX(A_Att,$R16)) -> 0.928 | P16: =IF($R16="","",INDEX(E_Overall,$R16)) -> 2.83 | Q16: =IF($R16="","",INDEX(E_Risk,$R16)) -> Medium | R16: =IF(B16="","",MATCH(B16,M_ID,0)) -> 12
A17: =IF(B17="","",13) -> 13 | B17: =IF(Calc_Engine!I14="","",Calc_Engine!I14) -> EMP1013 | C17: =IF($R17="","",INDEX(M_Name,$R17)) -> Ramya Khanna | D17: =IF($R17="","",INDEX(M_Title,$R17)) -> Compliance Manager | E17: =IF($R17="","",INDEX(M_Dept,$R17)) -> Legal & Compliance | F17: =IF($R17="","",INDEX(M_Level,$R17)) -> L5 | G17: =IF($R17="","",INDEX(M_Mgr,$R17)) -> Lakshmi Subramanian | H17: =IF($R17="","",INDEX(M_Status,$R17)) -> Active | I17: =IF($R17="","",INDEX(M_Tenure,$R17)) -> 6.7 | J17: =IF($R17="","",INDEX(P_Rating,$R17)) -> 3 | K17: =IF($R17="","",INDEX(P_9Box,$R17)) -> Core Player | L17: =IF($R17="","",INDEX(P_Elig,$R17)) -> Not Eligible | M17: =IF($R17="","",INDEX(C_CTC,$R17)/100000) -> 34.07 | N17: =IF($R17="","",INDEX(C_Compa,$R17)) -> 0.93 | O17: =IF($R17="","",INDEX(A_Att,$R17)) -> 0.928 | P17: =IF($R17="","",INDEX(E_Overall,$R17)) -> 3.33 | Q17: =IF($R17="","",INDEX(E_Risk,$R17)) -> Low | R17: =IF(B17="","",MATCH(B17,M_ID,0)) -> 13
A18: =IF(B18="","",14) -> 14 | B18: =IF(Calc_Engine!I15="","",Calc_Engine!I15) -> EMP1014 | C18: =IF($R18="","",INDEX(M_Name,$R18)) -> Rashmi Jain | D18: =IF($R18="","",INDEX(M_Title,$R18)) -> Senior HR Business Partner | E18: =IF($R18="","",INDEX(M_Dept,$R18)) -> Human Resources | F18: =IF($R18="","",INDEX(M_Level,$R18)) -> L4 | G18: =IF($R18="","",INDEX(M_Mgr,$R18)) -> Akash Das | H18: =IF($R18="","",INDEX(M_Status,$R18)) -> Active | I18: =IF($R18="","",INDEX(M_Tenure,$R18)) -> 6.5 | J18: =IF($R18="","",INDEX(P_Rating,$R18)) -> 3 | K18: =IF($R18="","",INDEX(P_9Box,$R18)) -> Future Star | L18: =IF($R18="","",INDEX(P_Elig,$R18)) -> Not Eligible | M18: =IF($R18="","",INDEX(C_CTC,$R18)/100000) -> 21.82 | N18: =IF($R18="","",INDEX(C_Compa,$R18)) -> 0.93 | O18: =IF($R18="","",INDEX(A_Att,$R18)) -> 0.956 | P18: =IF($R18="","",INDEX(E_Overall,$R18)) -> 3.28 | Q18: =IF($R18="","",INDEX(E_Risk,$R18)) -> Low | R18: =IF(B18="","",MATCH(B18,M_ID,0)) -> 14
A19: =IF(B19="","",15) -> 15 | B19: =IF(Calc_Engine!I16="","",Calc_Engine!I16) -> EMP1015 | C19: =IF($R19="","",INDEX(M_Name,$R19)) -> Ajay Ansari | D19: =IF($R19="","",INDEX(M_Title,$R19)) -> Operations Lead | E19: =IF($R19="","",INDEX(M_Dept,$R19)) -> Operations | F19: =IF($R19="","",INDEX(M_Level,$R19)) -> L4 | G19: =IF($R19="","",INDEX(M_Mgr,$R19)) -> Ankit Khanna | H19: =IF($R19="","",INDEX(M_Status,$R19)) -> Active | I19: =IF($R19="","",INDEX(M_Tenure,$R19)) -> 6.4 | J19: =IF($R19="","",INDEX(P_Rating,$R19)) -> 4 | K19: =IF($R19="","",INDEX(P_9Box,$R19)) -> Star | L19: =IF($R19="","",INDEX(P_Elig,$R19)) -> Not Eligible | M19: =IF($R19="","",INDEX(C_CTC,$R19)/100000) -> 19.91 | N19: =IF($R19="","",INDEX(C_Compa,$R19)) -> 0.85 | O19: =IF($R19="","",INDEX(A_Att,$R19)) -> 0.908 | P19: =IF($R19="","",INDEX(E_Overall,$R19)) -> 3.48 | Q19: =IF($R19="","",INDEX(E_Risk,$R19)) -> Medium | R19: =IF(B19="","",MATCH(B19,M_ID,0)) -> 15
A20: =IF(B20="","",16) -> 16 | B20: =IF(Calc_Engine!I17="","",Calc_Engine!I17) -> EMP1016 | C20: =IF($R20="","",INDEX(M_Name,$R20)) -> Isha Verma | D20: =IF($R20="","",INDEX(M_Title,$R20)) -> Support Manager | E20: =IF($R20="","",INDEX(M_Dept,$R20)) -> Customer Support | F20: =IF($R20="","",INDEX(M_Level,$R20)) -> L5 | G20: =IF($R20="","",INDEX(M_Mgr,$R20)) -> Akash Dsouza | H20: =IF($R20="","",INDEX(M_Status,$R20)) -> Active | I20: =IF($R20="","",INDEX(M_Tenure,$R20)) -> 6.4 | J20: =IF($R20="","",INDEX(P_Rating,$R20)) -> 3 | K20: =IF($R20="","",INDEX(P_9Box,$R20)) -> Future Star | L20: =IF($R20="","",INDEX(P_Elig,$R20)) -> Not Eligible | M20: =IF($R20="","",INDEX(C_CTC,$R20)/100000) -> 30.24 | N20: =IF($R20="","",INDEX(C_Compa,$R20)) -> 0.82 | O20: =IF($R20="","",INDEX(A_Att,$R20)) -> 0.916 | P20: =IF($R20="","",INDEX(E_Overall,$R20)) -> 3.17 | Q20: =IF($R20="","",INDEX(E_Risk,$R20)) -> Low | R20: =IF(B20="","",MATCH(B20,M_ID,0)) -> 16
A21: =IF(B21="","",17) -> 17 | B21: =IF(Calc_Engine!I18="","",Calc_Engine!I18) -> EMP1017 | C21: =IF($R21="","",INDEX(M_Name,$R21)) -> Pooja Naidu | D21: =IF($R21="","",INDEX(M_Title,$R21)) -> Tech Lead | E21: =IF($R21="","",INDEX(M_Dept,$R21)) -> Engineering | F21: =IF($R21="","",INDEX(M_Level,$R21)) -> L4 | G21: =IF($R21="","",INDEX(M_Mgr,$R21)) -> Harsh Siddiqui | H21: =IF($R21="","",INDEX(M_Status,$R21)) -> Active | I21: =IF($R21="","",INDEX(M_Tenure,$R21)) -> 6.3 | J21: =IF($R21="","",INDEX(P_Rating,$R21)) -> 5 | K21: =IF($R21="","",INDEX(P_9Box,$R21)) -> Star | L21: =IF($R21="","",INDEX(P_Elig,$R21)) -> Eligible | M21: =IF($R21="","",INDEX(C_CTC,$R21)/100000) -> 30.05 | N21: =IF($R21="","",INDEX(C_Compa,$R21)) -> 1.28 | O21: =IF($R21="","",INDEX(A_Att,$R21)) -> 0.904 | P21: =IF($R21="","",INDEX(E_Overall,$R21)) -> 3.9 | Q21: =IF($R21="","",INDEX(E_Risk,$R21)) -> Low | R21: =IF(B21="","",MATCH(B21,M_ID,0)) -> 17
A22: =IF(B22="","",18) -> 18 | B22: =IF(Calc_Engine!I19="","",Calc_Engine!I19) -> EMP1018 | C22: =IF($R22="","",INDEX(M_Name,$R22)) -> Isha Chatterjee | D22: =IF($R22="","",INDEX(M_Title,$R22)) -> Marketing Manager | E22: =IF($R22="","",INDEX(M_Dept,$R22)) -> Marketing | F22: =IF($R22="","",INDEX(M_Level,$R22)) -> L5 | G22: =IF($R22="","",INDEX(M_Mgr,$R22)) -> Aishwarya Mukherjee | H22: =IF($R22="","",INDEX(M_Status,$R22)) -> Exited | I22: =IF($R22="","",INDEX(M_Tenure,$R22)) -> 5.8 | J22: =IF($R22="","",INDEX(P_Rating,$R22)) -> 5 | K22: =IF($R22="","",INDEX(P_9Box,$R22)) -> High Performer | L22: =IF($R22="","",INDEX(P_Elig,$R22)) -> Not Eligible | M22: =IF($R22="","",INDEX(C_CTC,$R22)/100000) -> 34.3 | N22: =IF($R22="","",INDEX(C_Compa,$R22)) -> 0.94 | O22: =IF($R22="","",INDEX(A_Att,$R22)) -> 0.83211679 | P22: =IF($R22="","",INDEX(E_Overall,$R22)) -> 3.45 | Q22: =IF($R22="","",INDEX(E_Risk,$R22)) -> Exited | R22: =IF(B22="","",MATCH(B22,M_ID,0)) -> 18
A23: =IF(B23="","",19) -> 19 | B23: =IF(Calc_Engine!I20="","",Calc_Engine!I20) -> EMP1019 | C23: =IF($R23="","",INDEX(M_Name,$R23)) -> Fatima Reddy | D23: =IF($R23="","",INDEX(M_Title,$R23)) -> Key Account Manager | E23: =IF($R23="","",INDEX(M_Dept,$R23)) -> Sales | F23: =IF($R23="","",INDEX(M_Level,$R23)) -> L4 | G23: =IF($R23="","",INDEX(M_Mgr,$R23)) -> Srinivas Shah | H23: =IF($R23="","",INDEX(M_Status,$R23)) -> Active | I23: =IF($R23="","",INDEX(M_Tenure,$R23)) -> 6.2 | J23: =IF($R23="","",INDEX(P_Rating,$R23)) -> 3 | K23: =IF($R23="","",INDEX(P_9Box,$R23)) -> Core Player | L23: =IF($R23="","",INDEX(P_Elig,$R23)) -> Not Eligible | M23: =IF($R23="","",INDEX(C_CTC,$R23)/100000) -> 24.22 | N23: =IF($R23="","",INDEX(C_Compa,$R23)) -> 1.03 | O23: =IF($R23="","",INDEX(A_Att,$R23)) -> 0.92 | P23: =IF($R23="","",INDEX(E_Overall,$R23)) -> 2.33 | Q23: =IF($R23="","",INDEX(E_Risk,$R23)) -> Medium | R23: =IF(B23="","",MATCH(B23,M_ID,0)) -> 19
A24: =IF(B24="","",20) -> 20 | B24: =IF(Calc_Engine!I21="","",Calc_Engine!I21) -> EMP1020 | C24: =IF($R24="","",INDEX(M_Name,$R24)) -> Naveen Subramanian | D24: =IF($R24="","",INDEX(M_Title,$R24)) -> Support Team Lead | E24: =IF($R24="","",INDEX(M_Dept,$R24)) -> Customer Support | F24: =IF($R24="","",INDEX(M_Level,$R24)) -> L4 | G24: =IF($R24="","",INDEX(M_Mgr,$R24)) -> Ashish Varghese | H24: =IF($R24="","",INDEX(M_Status,$R24)) -> Active | I24: =IF($R24="","",INDEX(M_Tenure,$R24)) -> 6.2 | J24: =IF($R24="","",INDEX(P_Rating,$R24)) -> 3 | K24: =IF($R24="","",INDEX(P_9Box,$R24)) -> Core Player | L24: =IF($R24="","",INDEX(P_Elig,$R24)) -> Not Eligible | M24: =IF($R24="","",INDEX(C_CTC,$R24)/100000) -> 17.31 | N24: =IF($R24="","",INDEX(C_Compa,$R24)) -> 0.74 | O24: =IF($R24="","",INDEX(A_Att,$R24)) -> 0.956 | P24: =IF($R24="","",INDEX(E_Overall,$R24)) -> 3.4 | Q24: =IF($R24="","",INDEX(E_Risk,$R24)) -> Low | R24: =IF(B24="","",MATCH(B24,M_ID,0)) -> 20
A25: =IF(B25="","",21) -> 21 | B25: =IF(Calc_Engine!I22="","",Calc_Engine!I22) -> EMP1021 | C25: =IF($R25="","",INDEX(M_Name,$R25)) -> Arun Mukherjee | D25: =IF($R25="","",INDEX(M_Title,$R25)) -> Analytics Manager | E25: =IF($R25="","",INDEX(M_Dept,$R25)) -> Data & Analytics | F25: =IF($R25="","",INDEX(M_Level,$R25)) -> L5 | G25: =IF($R25="","",INDEX(M_Mgr,$R25)) -> Trisha Jain | H25: =IF($R25="","",INDEX(M_Status,$R25)) -> Active | I25: =IF($R25="","",INDEX(M_Tenure,$R25)) -> 6 | J25: =IF($R25="","",INDEX(P_Rating,$R25)) -> 3 | K25: =IF($R25="","",INDEX(P_9Box,$R25)) -> Future Star | L25: =IF($R25="","",INDEX(P_Elig,$R25)) -> Not Eligible | M25: =IF($R25="","",INDEX(C_CTC,$R25)/100000) -> 43.9 | N25: =IF($R25="","",INDEX(C_Compa,$R25)) -> 1.2 | O25: =IF($R25="","",INDEX(A_Att,$R25)) -> 0.952 | P25: =IF($R25="","",INDEX(E_Overall,$R25)) -> 3.53 | Q25: =IF($R25="","",INDEX(E_Risk,$R25)) -> Low | R25: =IF(B25="","",MATCH(B25,M_ID,0)) -> 21
A26: =IF(B26="","",22) -> 22 | B26: =IF(Calc_Engine!I23="","",Calc_Engine!I23) -> EMP1022 | C26: =IF($R26="","",INDEX(M_Name,$R26)) -> Arun Joshi | D26: =IF($R26="","",INDEX(M_Title,$R26)) -> Senior Data Analyst | E26: =IF($R26="","",INDEX(M_Dept,$R26)) -> Data & Analytics | F26: =IF($R26="","",INDEX(M_Level,$R26)) -> L3 | G26: =IF($R26="","",INDEX(M_Mgr,$R26)) -> Arun Mukherjee | H26: =IF($R26="","",INDEX(M_Status,$R26)) -> Active | I26: =IF($R26="","",INDEX(M_Tenure,$R26)) -> 6 | J26: =IF($R26="","",INDEX(P_Rating,$R26)) -> 3 | K26: =IF($R26="","",INDEX(P_9Box,$R26)) -> Effective Contributor | L26: =IF($R26="","",INDEX(P_Elig,$R26)) -> Not Eligible | M26: =IF($R26="","",INDEX(C_CTC,$R26)/100000) -> 15.59 | N26: =IF($R26="","",INDEX(C_Compa,$R26)) -> 1.08 | O26: =IF($R26="","",INDEX(A_Att,$R26)) -> 0.928 | P26: =IF($R26="","",INDEX(E_Overall,$R26)) -> 3.07 | Q26: =IF($R26="","",INDEX(E_Risk,$R26)) -> Low | R26: =IF(B26="","",MATCH(B26,M_ID,0)) -> 22
A27: =IF(B27="","",23) -> 23 | B27: =IF(Calc_Engine!I24="","",Calc_Engine!I24) -> EMP1023 | C27: =IF($R27="","",INDEX(M_Name,$R27)) -> Ashish Prabhu | D27: =IF($R27="","",INDEX(M_Title,$R27)) -> Senior Operations Executive | E27: =IF($R27="","",INDEX(M_Dept,$R27)) -> Operations | F27: =IF($R27="","",INDEX(M_Level,$R27)) -> L3 | G27: =IF($R27="","",INDEX(M_Mgr,$R27)) -> Ajay Kumar | H27: =IF($R27="","",INDEX(M_Status,$R27)) -> Active | I27: =IF($R27="","",INDEX(M_Tenure,$R27)) -> 6 | J27: =IF($R27="","",INDEX(P_Rating,$R27)) -> 3 | K27: =IF($R27="","",INDEX(P_9Box,$R27)) -> Core Player | L27: =IF($R27="","",INDEX(P_Elig,$R27)) -> Not Eligible | M27: =IF($R27="","",INDEX(C_CTC,$R27)/100000) -> 11.77 | N27: =IF($R27="","",INDEX(C_Compa,$R27)) -> 0.81 | O27: =IF($R27="","",INDEX(A_Att,$R27)) -> 0.944 | P27: =IF($R27="","",INDEX(E_Overall,$R27)) -> 3.48 | Q27: =IF($R27="","",INDEX(E_Risk,$R27)) -> Low | R27: =IF(B27="","",MATCH(B27,M_ID,0)) -> 23
A28: =IF(B28="","",24) -> 24 | B28: =IF(Calc_Engine!I25="","",Calc_Engine!I25) -> EMP1024 | C28: =IF($R28="","",INDEX(M_Name,$R28)) -> Priyanka Naidu | D28: =IF($R28="","",INDEX(M_Title,$R28)) -> HR Business Partner | E28: =IF($R28="","",INDEX(M_Dept,$R28)) -> Human Resources | F28: =IF($R28="","",INDEX(M_Level,$R28)) -> L3 | G28: =IF($R28="","",INDEX(M_Mgr,$R28)) -> Ajay Patel | H28: =IF($R28="","",INDEX(M_Status,$R28)) -> Active | I28: =IF($R28="","",INDEX(M_Tenure,$R28)) -> 6 | J28: =IF($R28="","",INDEX(P_Rating,$R28)) -> 4 | K28: =IF($R28="","",INDEX(P_9Box,$R28)) -> Star | L28: =IF($R28="","",INDEX(P_Elig,$R28)) -> Eligible | M28: =IF($R28="","",INDEX(C_CTC,$R28)/100000) -> 14.71 | N28: =IF($R28="","",INDEX(C_Compa,$R28)) -> 1.02 | O28: =IF($R28="","",INDEX(A_Att,$R28)) -> 0.952 | P28: =IF($R28="","",INDEX(E_Overall,$R28)) -> 3.53 | Q28: =IF($R28="","",INDEX(E_Risk,$R28)) -> Low | R28: =IF(B28="","",MATCH(B28,M_ID,0)) -> 24
A29: =IF(B29="","",25) -> 25 | B29: =IF(Calc_Engine!I26="","",Calc_Engine!I26) -> EMP1025 | C29: =IF($R29="","",INDEX(M_Name,$R29)) -> Nikhil Agarwal | D29: =IF($R29="","",INDEX(M_Title,$R29)) -> Sales Manager | E29: =IF($R29="","",INDEX(M_Dept,$R29)) -> Sales | F29: =IF($R29="","",INDEX(M_Level,$R29)) -> L5 | G29: =IF($R29="","",INDEX(M_Mgr,$R29)) -> Joseph Varghese | H29: =IF($R29="","",INDEX(M_Status,$R29)) -> Active | I29: =IF($R29="","",INDEX(M_Tenure,$R29)) -> 5.9 | J29: =IF($R29="","",INDEX(P_Rating,$R29)) -> 2 | K29: =IF($R29="","",INDEX(P_9Box,$R29)) -> Inconsistent Player | L29: =IF($R29="","",INDEX(P_Elig,$R29)) -> Not Eligible | M29: =IF($R29="","",INDEX(C_CTC,$R29)/100000) -> 35.26 | N29: =IF($R29="","",INDEX(C_Compa,$R29)) -> 0.96 | O29: =IF($R29="","",INDEX(A_Att,$R29)) -> 0.888 | P29: =IF($R29="","",INDEX(E_Overall,$R29)) -> 3.1 | Q29: =IF($R29="","",INDEX(E_Risk,$R29)) -> Low | R29: =IF(B29="","",MATCH(B29,M_ID,0)) -> 25
A30: =IF(B30="","",26) -> 26 | B30: =IF(Calc_Engine!I27="","",Calc_Engine!I27) -> EMP1026 | C30: =IF($R30="","",INDEX(M_Name,$R30)) -> Revathi Rao | D30: =IF($R30="","",INDEX(M_Title,$R30)) -> Senior Sales Executive | E30: =IF($R30="","",INDEX(M_Dept,$R30)) -> Sales | F30: =IF($R30="","",INDEX(M_Level,$R30)) -> L3 | G30: =IF($R30="","",INDEX(M_Mgr,$R30)) -> Yash Raghavan | H30: =IF($R30="","",INDEX(M_Status,$R30)) -> Exited | I30: =IF($R30="","",INDEX(M_Tenure,$R30)) -> 5.3 | J30: =IF($R30="","",INDEX(P_Rating,$R30)) -> 3 | K30: =IF($R30="","",INDEX(P_9Box,$R30)) -> Core Player | L30: =IF($R30="","",INDEX(P_Elig,$R30)) -> Not Eligible | M30: =IF($R30="","",INDEX(C_CTC,$R30)/100000) -> 16.07 | N30: =IF($R30="","",INDEX(C_Compa,$R30)) -> 1.11 | O30: =IF($R30="","",INDEX(A_Att,$R30)) -> 0.79775281 | P30: =IF($R30="","",INDEX(E_Overall,$R30)) -> 2.7 | Q30: =IF($R30="","",INDEX(E_Risk,$R30)) -> Exited | R30: =IF(B30="","",MATCH(B30,M_ID,0)) -> 26
A31: =IF(B31="","",27) -> 27 | B31: =IF(Calc_Engine!I28="","",Calc_Engine!I28) -> EMP1027 | C31: =IF($R31="","",INDEX(M_Name,$R31)) -> Yash Yadav | D31: =IF($R31="","",INDEX(M_Title,$R31)) -> Senior Software Engineer | E31: =IF($R31="","",INDEX(M_Dept,$R31)) -> Engineering | F31: =IF($R31="","",INDEX(M_Level,$R31)) -> L3 | G31: =IF($R31="","",INDEX(M_Mgr,$R31)) -> Bhavana Hegde | H31: =IF($R31="","",INDEX(M_Status,$R31)) -> Active | I31: =IF($R31="","",INDEX(M_Tenure,$R31)) -> 5.9 | J31: =IF($R31="","",INDEX(P_Rating,$R31)) -> 3 | K31: =IF($R31="","",INDEX(P_9Box,$R31)) -> Core Player | L31: =IF($R31="","",INDEX(P_Elig,$R31)) -> Not Eligible | M31: =IF($R31="","",INDEX(C_CTC,$R31)/100000) -> 14.29 | N31: =IF($R31="","",INDEX(C_Compa,$R31)) -> 0.99 | O31: =IF($R31="","",INDEX(A_Att,$R31)) -> 0.924 | P31: =IF($R31="","",INDEX(E_Overall,$R31)) -> 3.62 | Q31: =IF($R31="","",INDEX(E_Risk,$R31)) -> Low | R31: =IF(B31="","",MATCH(B31,M_ID,0)) -> 27
A32: =IF(B32="","",28) -> 28 | B32: =IF(Calc_Engine!I29="","",Calc_Engine!I29) -> EMP1028 | C32: =IF($R32="","",INDEX(M_Name,$R32)) -> Gayatri Krishnan | D32: =IF($R32="","",INDEX(M_Title,$R32)) -> Operations Lead | E32: =IF($R32="","",INDEX(M_Dept,$R32)) -> Operations | F32: =IF($R32="","",INDEX(M_Level,$R32)) -> L4 | G32: =IF($R32="","",INDEX(M_Mgr,$R32)) -> Ajay Kumar | H32: =IF($R32="","",INDEX(M_Status,$R32)) -> Exited | I32: =IF($R32="","",INDEX(M_Tenure,$R32)) -> 5.1 | J32: =IF($R32="","",INDEX(P_Rating,$R32)) -> 3 | K32: =IF($R32="","",INDEX(P_9Box,$R32)) -> Future Star | L32: =IF($R32="","",INDEX(P_Elig,$R32)) -> Not Eligible | M32: =IF($R32="","",INDEX(C_CTC,$R32)/100000) -> 18.79 | N32: =IF($R32="","",INDEX(C_Compa,$R32)) -> 0.8 | O32: =IF($R32="","",INDEX(A_Att,$R32)) -> 0.69387755 | P32: =IF($R32="","",INDEX(E_Overall,$R32)) -> 2.73 | Q32: =IF($R32="","",INDEX(E_Risk,$R32)) -> Exited | R32: =IF(B32="","",MATCH(B32,M_ID,0)) -> 28
